Workbook

Sheet Instructions for Use
C2: Instructions for data collection set up:
C4: 1 | D4: Save a copy of the Data Record in Individual Client File
C5: 2 | D5: Save using client code as the file name
C6: 3 | D6: Input data as follows:
E7: Data input sheets
F8: Demographics | G8: Input from Treatment Plan
F9: Goal Based Outcomes | G9: Input from Goal Based Outcome forms (enter as many as received i.e. Parent/Carer 1, Parent Carer 2, School, Self)
F10: SDQ's | G10: Include SDQ's from school, parent/carer, self as required for 3 data collection periods
C11: 4 | D11: Check data is complete and accurate by reviewing the answers in the data check boxes. Correct any errors or comment on the audit page.
F12: On GBO worksheet
F13: On each SDQ worksheet
C15: 5 | D15: Review the Audit tab | F15: Purpose: therapist and reviewer to review checks, amend errors/omissions if necessary
F16: Output: determine if file can be included in research
F17: Inputs: client code, GDPR consent, specify data points of data being collected, check sequentially entered
C19: To protect the integrity of the data the cells are colour co-ordinated:
F21: Requires input
F23: Required selection of drop-down criteria
F25: Cells are calculated automatically and cannot be selected

Sheet <<<Data Input>>>
C5: To protect the integrity of the data the cells are colour co-ordinated:
F7: Requires input
F9: Requires selection of drop-down criteria
F11: Cells are calculated automatically and cannot be selected
C13: Data to be populated from the following information sources:
E14: Demographics from treatment plan and intake meeting
E15: Goal based outcomes - by completed form. May have 1 parent, 2 parents, school or older young person. Does not have to be all.
E16: SDQ forms by school, parent/carer, self. Does not have to be all.

Sheet Demographic Information
A1: Date of Birth | B1: Gender/Sex | C1: Council | D1: Ethnicity | E1: English as an Additional Language | F1: Disability Status | G1: Disability Type | H1: Care Experience | I1: Intervention Type | J1: Additional Intervention Type | K1: Additional Intervention Type | L1: Additional Intervention Type | M1: ACES | N1: Funding source
A2: 30529 | B2: Male | C2: Gloucester City | D2: White British | E2: No | F2: Disability | G2: Sensory Impairment (e.g. hearing or visual) | H2: Yes - Adopted | I2: CPRT | J2: PTP | K2: IA | L2: CPRT | M2: 3 | N2: ASGSF

Sheet Goal Based Outcomes (GBO)
C2: Instructions for completion: | D2: GBO's can be completed by any or all of the following: Parent/Carer 1, Parent/Carer 2, School, Self
D3: Input : initials of parent to ensure consistency of reporting (data not used elsewhere)
D4: Select GBO: 1-6 (as many as required) from drop down box and input scores by period
D5: Specify period: add date form was completed
D6: Review: data checks for any error messages and amend as necessary
C9: Initials of Parent/Carer for consistency | E9: Goal Based Outcome - Completed by Parent/Carer 1
E10: 1 | F10: 2 | G10: 3 | H10: 4 | I10: 5 | J10: 6
L11: Data Checks - Confirms if Data in Any of the 4 Forms per Period
C12: Data Input | D12: Specify Period | E12: Score | F12: Score | G12: Score | H12: Score | I12: Score | J12: Score | L12: 1 | M12: 2 | N12: 3 | O12: 4 | P12: 5 | Q12: 6
C13: Period 1 | D13: 45880 | E13: 4 | F13: 5 | G13: 6 | H13: 7 | L13: =IF(OR(LEN(TRIM(E13))>0, LEN(TRIM(E36))>0, LEN(TRIM(E59))>0, LEN(TRIM(E82))>0), "✓", "") -> ✓ | M13: =IF(OR(LEN(TRIM(F13))>0, LEN(TRIM(F36))>0, LEN(TRIM(F59))>0, LEN(TRIM(F82))>0), "✓", "") -> ✓ | N13: =IF(OR(LEN(TRIM(G13))>0, LEN(TRIM(G36))>0, LEN(TRIM(G59))>0, LEN(TRIM(G82))>0), "✓", "") -> ✓ | O13: =IF(OR(LEN(TRIM(H13))>0, LEN(TRIM(H36))>0, LEN(TRIM(H59))>0, LEN(TRIM(H82))>0), "✓", "") -> ✓ | P13: =IF(OR(LEN(TRIM(I13))>0, LEN(TRIM(I36))>0, LEN(TRIM(I59))>0, LEN(TRIM(I82))>0), "✓", "") | Q13: =IF(OR(LEN(TRIM(J13))>0, LEN(TRIM(J36))>0, LEN(TRIM(J59))>0, LEN(TRIM(J82))>0), "✓", "")
C14: Period 2 | D14: 45911 | E14: 6 | F14: 6 | G14: 7 | H14: 8 | L14: =IF(OR(LEN(TRIM(E14))>0, LEN(TRIM(E37))>0, LEN(TRIM(E60))>0, LEN(TRIM(E83))>0), "✓", "") -> ✓ | M14: =IF(OR(LEN(TRIM(F14))>0, LEN(TRIM(F37))>0, LEN(TRIM(F60))>0, LEN(TRIM(F83))>0), "✓", "") -> ✓ | N14: =IF(OR(LEN(TRIM(G14))>0, LEN(TRIM(G37))>0, LEN(TRIM(G60))>0, LEN(TRIM(G83))>0), "✓", "") -> ✓ | O14: =IF(OR(LEN(TRIM(H14))>0, LEN(TRIM(H37))>0, LEN(TRIM(H60))>0, LEN(TRIM(H83))>0), "✓", "") -> ✓ | P14: =IF(OR(LEN(TRIM(I14))>0, LEN(TRIM(I37))>0, LEN(TRIM(I60))>0, LEN(TRIM(I83))>0), "✓", "") | Q14: =IF(OR(LEN(TRIM(J14))>0, LEN(TRIM(J37))>0, LEN(TRIM(J60))>0, LEN(TRIM(J83))>0), "✓", "")
C15: Period 3 | L15: =IF(OR(LEN(TRIM(E15))>0, LEN(TRIM(E38))>0, LEN(TRIM(E61))>0, LEN(TRIM(E84))>0), "✓", "") | M15: =IF(OR(LEN(TRIM(F15))>0, LEN(TRIM(F38))>0, LEN(TRIM(F61))>0, LEN(TRIM(F84))>0), "✓", "") | N15: =IF(OR(LEN(TRIM(G15))>0, LEN(TRIM(G38))>0, LEN(TRIM(G61))>0, LEN(TRIM(G84))>0), "✓", "") | O15: =IF(OR(LEN(TRIM(H15))>0, LEN(TRIM(H38))>0, LEN(TRIM(H61))>0, LEN(TRIM(H84))>0), "✓", "") | P15: =IF(OR(LEN(TRIM(I15))>0, LEN(TRIM(I38))>0, LEN(TRIM(I61))>0, LEN(TRIM(I84))>0), "✓", "") | Q15: =IF(OR(LEN(TRIM(J15))>0, LEN(TRIM(J38))>0, LEN(TRIM(J61))>0, LEN(TRIM(J84))>0), "✓", "")
C16: Period 4 | L16: =IF(OR(LEN(TRIM(E16))>0, LEN(TRIM(E39))>0, LEN(TRIM(E62))>0, LEN(TRIM(E85))>0), "✓", "") | M16: =IF(OR(LEN(TRIM(F16))>0, LEN(TRIM(F39))>0, LEN(TRIM(F62))>0, LEN(TRIM(F85))>0), "✓", "") | N16: =IF(OR(LEN(TRIM(G16))>0, LEN(TRIM(G39))>0, LEN(TRIM(G62))>0, LEN(TRIM(G85))>0), "✓", "") | O16: =IF(OR(LEN(TRIM(H16))>0, LEN(TRIM(H39))>0, LEN(TRIM(H62))>0, LEN(TRIM(H85))>0), "✓", "") | P16: =IF(OR(LEN(TRIM(I16))>0, LEN(TRIM(I39))>0, LEN(TRIM(I62))>0, LEN(TRIM(I85))>0), "✓", "") | Q16: =IF(OR(LEN(TRIM(J16))>0, LEN(TRIM(J39))>0, LEN(TRIM(J62))>0, LEN(TRIM(J85))>0), "✓", "")
C17: Period 5 | L17: =IF(OR(LEN(TRIM(E17))>0, LEN(TRIM(E40))>0, LEN(TRIM(E63))>0, LEN(TRIM(E86))>0), "✓", "") | M17: =IF(OR(LEN(TRIM(F17))>0, LEN(TRIM(F40))>0, LEN(TRIM(F63))>0, LEN(TRIM(F86))>0), "✓", "") | N17: =IF(OR(LEN(TRIM(G17))>0, LEN(TRIM(G40))>0, LEN(TRIM(G63))>0, LEN(TRIM(G86))>0), "✓", "") | O17: =IF(OR(LEN(TRIM(H17))>0, LEN(TRIM(H40))>0, LEN(TRIM(H63))>0, LEN(TRIM(H86))>0), "✓", "") | P17: =IF(OR(LEN(TRIM(I17))>0, LEN(TRIM(I40))>0, LEN(TRIM(I63))>0, LEN(TRIM(I86))>0), "✓", "") | Q17: =IF(OR(LEN(TRIM(J17))>0, LEN(TRIM(J40))>0, LEN(TRIM(J63))>0, LEN(TRIM(J86))>0), "✓", "")
C18: Period 6 | L18: =IF(OR(LEN(TRIM(E18))>0, LEN(TRIM(E41))>0, LEN(TRIM(E64))>0, LEN(TRIM(E87))>0), "✓", "") | M18: =IF(OR(LEN(TRIM(F18))>0, LEN(TRIM(F41))>0, LEN(TRIM(F64))>0, LEN(TRIM(F87))>0), "✓", "") | N18: =IF(OR(LEN(TRIM(G18))>0, LEN(TRIM(G41))>0, LEN(TRIM(G64))>0, LEN(TRIM(G87))>0), "✓", "") | O18: =IF(OR(LEN(TRIM(H18))>0, LEN(TRIM(H41))>0, LEN(TRIM(H64))>0, LEN(TRIM(H87))>0), "✓", "") | P18: =IF(OR(LEN(TRIM(I18))>0, LEN(TRIM(I41))>0, LEN(TRIM(I64))>0, LEN(TRIM(I87))>0), "✓", "") | Q18: =IF(OR(LEN(TRIM(J18))>0, LEN(TRIM(J41))>0, LEN(TRIM(J64))>0, LEN(TRIM(J87))>0), "✓", "")
C19: Period 7 | L19: =IF(OR(LEN(TRIM(E19))>0, LEN(TRIM(E42))>0, LEN(TRIM(E65))>0, LEN(TRIM(E88))>0), "✓", "") | M19: =IF(OR(LEN(TRIM(F19))>0, LEN(TRIM(F42))>0, LEN(TRIM(F65))>0, LEN(TRIM(F88))>0), "✓", "") | N19: =IF(OR(LEN(TRIM(G19))>0, LEN(TRIM(G42))>0, LEN(TRIM(G65))>0, LEN(TRIM(G88))>0), "✓", "") | O19: =IF(OR(LEN(TRIM(H19))>0, LEN(TRIM(H42))>0, LEN(TRIM(H65))>0, LEN(TRIM(H88))>0), "✓", "") | P19: =IF(OR(LEN(TRIM(I19))>0, LEN(TRIM(I42))>0, LEN(TRIM(I65))>0, LEN(TRIM(I88))>0), "✓", "") | Q19: =IF(OR(LEN(TRIM(J19))>0, LEN(TRIM(J42))>0, LEN(TRIM(J65))>0, LEN(TRIM(J88))>0), "✓", "")
C20: Period 8 | L20: =IF(OR(LEN(TRIM(E20))>0, LEN(TRIM(E43))>0, LEN(TRIM(E66))>0, LEN(TRIM(E89))>0), "✓", "") | M20: =IF(OR(LEN(TRIM(F20))>0, LEN(TRIM(F43))>0, LEN(TRIM(F66))>0, LEN(TRIM(F89))>0), "✓", "") | N20: =IF(OR(LEN(TRIM(G20))>0, LEN(TRIM(G43))>0, LEN(TRIM(G66))>0, LEN(TRIM(G89))>0), "✓", "") | O20: =IF(OR(LEN(TRIM(H20))>0, LEN(TRIM(H43))>0, LEN(TRIM(H66))>0, LEN(TRIM(H89))>0), "✓", "") | P20: =IF(OR(LEN(TRIM(I20))>0, LEN(TRIM(I43))>0, LEN(TRIM(I66))>0, LEN(TRIM(I89))>0), "✓", "") | Q20: =IF(OR(LEN(TRIM(J20))>0, LEN(TRIM(J43))>0, LEN(TRIM(J66))>0, LEN(TRIM(J89))>0), "✓", "")
C21: Period 9 | L21: =IF(OR(LEN(TRIM(E21))>0, LEN(TRIM(E44))>0, LEN(TRIM(E67))>0, LEN(TRIM(E90))>0), "✓", "") | M21: =IF(OR(LEN(TRIM(F21))>0, LEN(TRIM(F44))>0, LEN(TRIM(F67))>0, LEN(TRIM(F90))>0), "✓", "") | N21: =IF(OR(LEN(TRIM(G21))>0, LEN(TRIM(G44))>0, LEN(TRIM(G67))>0, LEN(TRIM(G90))>0), "✓", "") | O21: =IF(OR(LEN(TRIM(H21))>0, LEN(TRIM(H44))>0, LEN(TRIM(H67))>0, LEN(TRIM(H90))>0), "✓", "") | P21: =IF(OR(LEN(TRIM(I21))>0, LEN(TRIM(I44))>0, LEN(TRIM(I67))>0, LEN(TRIM(I90))>0), "✓", "") | Q21: =IF(OR(LEN(TRIM(J21))>0, LEN(TRIM(J44))>0, LEN(TRIM(J67))>0, LEN(TRIM(J90))>0), "✓", "")
C22: Period 10 | L22: =IF(OR(LEN(TRIM(E22))>0, LEN(TRIM(E45))>0, LEN(TRIM(E68))>0, LEN(TRIM(E91))>0), "✓", "") | M22: =IF(OR(LEN(TRIM(F22))>0, LEN(TRIM(F45))>0, LEN(TRIM(F68))>0, LEN(TRIM(F91))>0), "✓", "") | N22: =IF(OR(LEN(TRIM(G22))>0, LEN(TRIM(G45))>0, LEN(TRIM(G68))>0, LEN(TRIM(G91))>0), "✓", "") | O22: =IF(OR(LEN(TRIM(H22))>0, LEN(TRIM(H45))>0, LEN(TRIM(H68))>0, LEN(TRIM(H91))>0), "✓", "") | P22: =IF(OR(LEN(TRIM(I22))>0, LEN(TRIM(I45))>0, LEN(TRIM(I68))>0, LEN(TRIM(I91))>0), "✓", "") | Q22: =IF(OR(LEN(TRIM(J22))>0, LEN(TRIM(J45))>0, LEN(TRIM(J68))>0, LEN(TRIM(J91))>0), "✓", "")
C23: Period 11 | L23: =IF(OR(LEN(TRIM(E23))>0, LEN(TRIM(E46))>0, LEN(TRIM(E69))>0, LEN(TRIM(E92))>0), "✓", "") | M23: =IF(OR(LEN(TRIM(F23))>0, LEN(TRIM(F46))>0, LEN(TRIM(F69))>0, LEN(TRIM(F92))>0), "✓", "") | N23: =IF(OR(LEN(TRIM(G23))>0, LEN(TRIM(G46))>0, LEN(TRIM(G69))>0, LEN(TRIM(G92))>0), "✓", "") | O23: =IF(OR(LEN(TRIM(H23))>0, LEN(TRIM(H46))>0, LEN(TRIM(H69))>0, LEN(TRIM(H92))>0), "✓", "") | P23: =IF(OR(LEN(TRIM(I23))>0, LEN(TRIM(I46))>0, LEN(TRIM(I69))>0, LEN(TRIM(I92))>0), "✓", "") | Q23: =IF(OR(LEN(TRIM(J23))>0, LEN(TRIM(J46))>0, LEN(TRIM(J69))>0, LEN(TRIM(J92))>0), "✓", "")
C24: Period 12 | L24: =IF(OR(LEN(TRIM(E24))>0, LEN(TRIM(E47))>0, LEN(TRIM(E70))>0, LEN(TRIM(E93))>0), "✓", "") | M24: =IF(OR(LEN(TRIM(F24))>0, LEN(TRIM(F47))>0, LEN(TRIM(F70))>0, LEN(TRIM(F93))>0), "✓", "") | N24: =IF(OR(LEN(TRIM(G24))>0, LEN(TRIM(G47))>0, LEN(TRIM(G70))>0, LEN(TRIM(G93))>0), "✓", "") | O24: =IF(OR(LEN(TRIM(H24))>0, LEN(TRIM(H47))>0, LEN(TRIM(H70))>0, LEN(TRIM(H93))>0), "✓", "") | P24: =IF(OR(LEN(TRIM(I24))>0, LEN(TRIM(I47))>0, LEN(TRIM(I70))>0, LEN(TRIM(I93))>0), "✓", "") | Q24: =IF(OR(LEN(TRIM(J24))>0, LEN(TRIM(J47))>0, LEN(TRIM(J70))>0, LEN(TRIM(J93))>0), "✓", "")
C25: Period 13 | L25: =IF(OR(LEN(TRIM(E25))>0, LEN(TRIM(E48))>0, LEN(TRIM(E71))>0, LEN(TRIM(E94))>0), "✓", "") | M25: =IF(OR(LEN(TRIM(F25))>0, LEN(TRIM(F48))>0, LEN(TRIM(F71))>0, LEN(TRIM(F94))>0), "✓", "") | N25: =IF(OR(LEN(TRIM(G25))>0, LEN(TRIM(G48))>0, LEN(TRIM(G71))>0, LEN(TRIM(G94))>0), "✓", "") | O25: =IF(OR(LEN(TRIM(H25))>0, LEN(TRIM(H48))>0, LEN(TRIM(H71))>0, LEN(TRIM(H94))>0), "✓", "") | P25: =IF(OR(LEN(TRIM(I25))>0, LEN(TRIM(I48))>0, LEN(TRIM(I71))>0, LEN(TRIM(I94))>0), "✓", "") | Q25: =IF(OR(LEN(TRIM(J25))>0, LEN(TRIM(J48))>0, LEN(TRIM(J71))>0, LEN(TRIM(J94))>0), "✓", "")
C26: Period 14 | L26: =IF(OR(LEN(TRIM(E26))>0, LEN(TRIM(E49))>0, LEN(TRIM(E72))>0, LEN(TRIM(E95))>0), "✓", "") | M26: =IF(OR(LEN(TRIM(F26))>0, LEN(TRIM(F49))>0, LEN(TRIM(F72))>0, LEN(TRIM(F95))>0), "✓", "") | N26: =IF(OR(LEN(TRIM(G26))>0, LEN(TRIM(G49))>0, LEN(TRIM(G72))>0, LEN(TRIM(G95))>0), "✓", "") | O26: =IF(OR(LEN(TRIM(H26))>0, LEN(TRIM(H49))>0, LEN(TRIM(H72))>0, LEN(TRIM(H95))>0), "✓", "") | P26: =IF(OR(LEN(TRIM(I26))>0, LEN(TRIM(I49))>0, LEN(TRIM(I72))>0, LEN(TRIM(I95))>0), "✓", "") | Q26: =IF(OR(LEN(TRIM(J26))>0, LEN(TRIM(J49))>0, LEN(TRIM(J72))>0, LEN(TRIM(J95))>0), "✓", "")
... C30: Period 18 | L30: =IF(OR(LEN(TRIM(E30))>0, LEN(TRIM(E53))>0, LEN(TRIM(E76))>0, LEN(TRIM(E99))>0), "✓", "") | M30: =IF(OR(LEN(TRIM(F30))>0, LEN(TRIM(F53))>0, LEN(TRIM(F76))>0, LEN(TRIM(F99))>0), "✓", "") | N30: =IF(OR(LEN(TRIM(G30))>0, LEN(TRIM(G53))>0, LEN(TRIM(G76))>0, LEN(TRIM(G99))>0), "✓", "") | O30: =IF(OR(LEN(TRIM(H30))>0, LEN(TRIM(H53))>0, LEN(TRIM(H76))>0, LEN(TRIM(H99))>0), "✓", "") | P30: =IF(OR(LEN(TRIM(I30))>0, LEN(TRIM(I53))>0, LEN(TRIM(I76))>0, LEN(TRIM(I99))>0), "✓", "") | Q30: =IF(OR(LEN(TRIM(J30))>0, LEN(TRIM(J53))>0, LEN(TRIM(J76))>0, LEN(TRIM(J99))>0), "✓", "")
C32: Initials of Parent/Carer for consistency | E32: Goal Based Outcome - Completed by Parent/Carer 2
E33: 1 | F33: 2 | G33: 3 | H33: 4 | I33: 5 | J33: 6 | L33: =IF(COUNTIF(L13:L21,"✓")=0, "", IF(OR( AND(L13="✓", L14="✓", L15="✓"), AND(L14="✓", L15="✓", L16="✓"), AND(L15="✓", L16="✓", L17="✓"), AND(L16="✓", L17="✓", L18="✓"), AND(L17="✓", L18="✓", L19="✓"), AND(L18="✓", L19="✓", L20="✓"), AND(L19="✓", L20="✓", L21="✓") ), "Complete", "Incomplete")) -> Incomplete | M33: =IF(COUNTIF(M13:M21,"✓")=0, "", IF(OR( AND(M13="✓", M14="✓", M15="✓"), AND(M14="✓", M15="✓", M16="✓"), AND(M15="✓", M16="✓", M17="✓"), AND(M16="✓", M17="✓", M18="✓"), AND(M17="✓", M18="✓", M19="✓"), AND(M18="✓", M19="✓", M20="✓"), AND(M19="✓", M20="✓", M21="✓") ), "Complete", "Incomplete")) -> Incomplete | N33: =IF(COUNTIF(N13:N21,"✓")=0, "", IF(OR( AND(N13="✓", N14="✓", N15="✓"), AND(N14="✓", N15="✓", N16="✓"), AND(N15="✓", N16="✓", N17="✓"), AND(N16="✓", N17="✓", N18="✓"), AND(N17="✓", N18="✓", N19="✓"), AND(N18="✓", N19="✓", N20="✓"), AND(N19="✓", N20="✓", N21="✓") ), "Complete", "Incomplete")) -> Incomplete | O33: =IF(COUNTIF(O13:O21,"✓")=0, "", IF(OR( AND(O13="✓", O14="✓", O15="✓"), AND(O14="✓", O15="✓", O16="✓"), AND(O15="✓", O16="✓", O17="✓"), AND(O16="✓", O17="✓", O18="✓"), AND(O17="✓", O18="✓", O19="✓"), AND(O18="✓", O19="✓", O20="✓"), AND(O19="✓", O20="✓", O21="✓") ), "Complete", "Incomplete")) -> Incomplete | P33: =IF(COUNTIF(P13:P21,"✓")=0, "", IF(OR( AND(P13="✓", P14="✓", P15="✓"), AND(P14="✓", P15="✓", P16="✓"), AND(P15="✓", P16="✓", P17="✓"), AND(P16="✓", P17="✓", P18="✓"), AND(P17="✓", P18="✓", P19="✓"), AND(P18="✓", P19="✓", P20="✓"), AND(P19="✓", P20="✓", P21="✓") ), "Complete", "Incomplete")) | Q33: =IF(COUNTIF(Q13:Q21,"✓")=0, "", IF(OR( AND(Q13="✓", Q14="✓", Q15="✓"), AND(Q14="✓", Q15="✓", Q16="✓"), AND(Q15="✓", Q16="✓", Q17="✓"), AND(Q16="✓", Q17="✓", Q18="✓"), AND(Q17="✓", Q18="✓", Q19="✓"), AND(Q18="✓", Q19="✓", Q20="✓"), AND(Q19="✓", Q20="✓", Q21="✓") ), "Complete", "Incomplete"))
C35: Data Input | D35: Specify Period | E35: Score | F35: Score | G35: Score | H35: Score | I35: Score | J35: Score | L35: Checks sequential inputting of data to make sure in correct date order | Q35: Summary
C36: Period 1 | D36: 45880 | E36: 4 | F36: 5 | G36: 6 | H36: 7 | L36: Parent/Carer 1 | M36: Parent/Carer 2 | N36: School | O36: Self | Q36: =IF(COUNTIF(L37:O53, "✓")+COUNTIF(L37:O53, "⚠️ Not in Order")=0, "", IF(COUNTIF(L37:O53, "⚠️ Not in Order")>0, "⚠️ Not in Order", "✓ All in Order")) -> ✓ All in Order
C37: Period 2 | D37: 45911 | E37: 6 | F37: 6 | G37: 7 | H37: 8 | L37: =IF(OR(D14="", D13=""), "", IF(D14>=D13, "✓", "⚠️ Not in Order")) -> ✓ | M37: =IF(OR(D37="", D36=""), "", IF(D37>=D36, "✓", "⚠️ Not in Order")) -> ✓ | N37: =IF(OR(D60="", D59=""), "", IF(D60>=D59, "✓", "⚠️ Not in Order")) -> ✓ | O37: =IF(OR(D83="", D82=""), "", IF(D83>=D82, "✓", "⚠️ Not in Order")) -> ✓
C38: Period 3 | L38: =IF(OR(D15="", D14=""), "", IF(D15>=D14, "✓", "⚠️ Not in Order")) | M38: =IF(OR(D38="", D37=""), "", IF(D38>=D37, "✓", "⚠️ Not in Order")) | N38: =IF(OR(D61="", D60=""), "", IF(D61>=D60, "✓", "⚠️ Not in Order")) | O38: =IF(OR(D84="", D83=""), "", IF(D84>=D83, "✓", "⚠️ Not in Order"))
C39: Period 4 | L39: =IF(OR(D16="", D15=""), "", IF(D16>=D15, "✓", "⚠️ Not in Order")) | M39: =IF(OR(D39="", D38=""), "", IF(D39>=D38, "✓", "⚠️ Not in Order")) | N39: =IF(OR(D62="", D61=""), "", IF(D62>=D61, "✓", "⚠️ Not in Order")) | O39: =IF(OR(D85="", D84=""), "", IF(D85>=D84, "✓", "⚠️ Not in Order"))
C40: Period 5 | L40: =IF(OR(D17="", D16=""), "", IF(D17>=D16, "✓", "⚠️ Not in Order")) | M40: =IF(OR(D40="", D39=""), "", IF(D40>=D39, "✓", "⚠️ Not in Order")) | N40: =IF(OR(D63="", D62=""), "", IF(D63>=D62, "✓", "⚠️ Not in Order")) | O40: =IF(OR(D86="", D85=""), "", IF(D86>=D85, "✓", "⚠️ Not in Order"))
C41: Period 6 | L41: =IF(OR(D18="", D17=""), "", IF(D18>=D17, "✓", "⚠️ Not in Order")) | M41: =IF(OR(D41="", D40=""), "", IF(D41>=D40, "✓", "⚠️ Not in Order")) | N41: =IF(OR(D64="", D63=""), "", IF(D64>=D63, "✓", "⚠️ Not in Order")) | O41: =IF(OR(D87="", D86=""), "", IF(D87>=D86, "✓", "⚠️ Not in Order"))
C42: Period 7 | L42: =IF(OR(D19="", D18=""), "", IF(D19>=D18, "✓", "⚠️ Not in Order")) | M42: =IF(OR(D42="", D41=""), "", IF(D42>=D41, "✓", "⚠️ Not in Order")) | N42: =IF(OR(D65="", D64=""), "", IF(D65>=D64, "✓", "⚠️ Not in Order")) | O42: =IF(OR(D88="", D87=""), "", IF(D88>=D87, "✓", "⚠️ Not in Order"))
C43: Period 8 | L43: =IF(OR(D20="", D19=""), "", IF(D20>=D19, "✓", "⚠️ Not in Order")) | M43: =IF(OR(D43="", D42=""), "", IF(D43>=D42, "✓", "⚠️ Not in Order")) | N43: =IF(OR(D66="", D65=""), "", IF(D66>=D65, "✓", "⚠️ Not in Order")) | O43: =IF(OR(D89="", D88=""), "", IF(D89>=D88, "✓", "⚠️ Not in Order"))
C44: Period 9 | L44: =IF(OR(D21="", D20=""), "", IF(D21>=D20, "✓", "⚠️ Not in Order")) | M44: =IF(OR(D44="", D43=""), "", IF(D44>=D43, "✓", "⚠️ Not in Order")) | N44: =IF(OR(D67="", D66=""), "", IF(D67>=D66, "✓", "⚠️ Not in Order")) | O44: =IF(OR(D90="", D89=""), "", IF(D90>=D89, "✓", "⚠️ Not in Order"))
C45: Period 10 | L45: =IF(OR(D22="", D21=""), "", IF(D22>=D21, "✓", "⚠️ Not in Order")) | M45: =IF(OR(D45="", D44=""), "", IF(D45>=D44, "✓", "⚠️ Not in Order")) | N45: =IF(OR(D68="", D67=""), "", IF(D68>=D67, "✓", "⚠️ Not in Order")) | O45: =IF(OR(D91="", D90=""), "", IF(D91>=D90, "✓", "⚠️ Not in Order"))
C46: Period 11 | L46: =IF(OR(D23="", D22=""), "", IF(D23>=D22, "✓", "⚠️ Not in Order")) | M46: =IF(OR(D46="", D45=""), "", IF(D46>=D45, "✓", "⚠️ Not in Order")) | N46: =IF(OR(D69="", D68=""), "", IF(D69>=D68, "✓", "⚠️ Not in Order")) | O46: =IF(OR(D92="", D91=""), "", IF(D92>=D91, "✓", "⚠️ Not in Order"))
C47: Period 12 | L47: =IF(OR(D24="", D23=""), "", IF(D24>=D23, "✓", "⚠️ Not in Order")) | M47: =IF(OR(D47="", D46=""), "", IF(D47>=D46, "✓", "⚠️ Not in Order")) | N47: =IF(OR(D70="", D69=""), "", IF(D70>=D69, "✓", "⚠️ Not in Order")) | O47: =IF(OR(D93="", D92=""), "", IF(D93>=D92, "✓", "⚠️ Not in Order"))
C48: Period 13 | L48: =IF(OR(D25="", D24=""), "", IF(D25>=D24, "✓", "⚠️ Not in Order")) | M48: =IF(OR(D48="", D47=""), "", IF(D48>=D47, "✓", "⚠️ Not in Order")) | N48: =IF(OR(D71="", D70=""), "", IF(D71>=D70, "✓", "⚠️ Not in Order")) | O48: =IF(OR(D94="", D93=""), "", IF(D94>=D93, "✓", "⚠️ Not in Order"))
...

Sheet SDQ Period 1
C2: Instructions: | D2: Input: SDQ scores from Parent/Carer, School or Self Forms
D3: Input and calculate: Impact Score
D4: Check data: input table for errors/omissions and amend data as necessary
C6: Specify Date
B8: Parent/ Carer 1 Completed SDQ | E8: Initials for consistency
C10: Category | D10: Statement | E10: Not True | F10: Sometimes | G10: TRUE
D11: Score | E11: 0 or 2 | F11: 1 | G11: 2 or 0 | J11: Note: the 3 scoring columns below are formula driven so the cell cannot be altered EXCEPT for the colour to indicate changes in scores
D12: 1. Considerate of other people’s feelings | E12: 0
C13: HyperActivity | D13: 2. Restless, overactive, cannot stay still for long | F13: 1 | J13: Scores
C14: Emotional | D14: 3. Often complains of headaches, stomach-aches or sickness | G14: 2 | J14: Category | K14: Parent/Carer 1 Score | L14: Parent/Carer 2 Score | M14: School Score | N14: Self Score | O14: Comparison - taken from parent scores only
C15: Pro Social | D15: 4. Shares readily with other children (treats, toys, pencils etc) | G15: 2 | J15: Emotional | K15: =SUM(E14,F14,G14,E19,F19,G19,E27,F27,G27,E24,F24,G24,E35,F35,G35) -> 7 | L15: =SUM(E47,F47,G47,E52,F52,G52,E60,F60,G60,E57,F57,G57,E68,F68,G68) -> 8 | M15: =SUM(E78,F78,G78,E83,F83,G83,E91,F91,G91,E88,F88,G88,E99,F99,G99) -> 7 | N15: =SUM(E108,F108,G108,E113,F113,G113,E118,F118,G118,E121,F121,G121,E129,F129,G129) -> 7 | O15: 0-3 | P15: 4 | Q15: 5-6 | R15: 7-10
C16: Conduct | D16: 5. Often has temper tantrums or hot tempers | F16: 1 | J16: Peer | K16: =SUM(E17,F17,G17,E22,F22,G22,E25,F25,G25,E30,F30,G30,E34,F34,G34) -> 4 | L16: =SUM(E50,F50,G50,E55,F55,G55,E58,F58,G58,E63,F63,G63,E67,F67,G67) -> 3 | M16: =SUM(E81,F81,G81,E86,F86,G86,E89,F89,G89,E94,F94,G94,E98,F98,G98) -> 3 | N16: =SUM(E111,F111,G111,E116,F116,G116,E119,F119,G119,E124,F124,G124,E128,F128,G128) -> 4 | O16: 0-2 | P16: 3 | Q16: 4 | R16: 5-10
C17: Peer | D17: 6. Rather solitary, tends to play alone | E17: 1 | J17: Conduct | K17: =SUM(E16,F16,G16,E18,F18,G18,E23,F23,G23,E29,F29,G29,E33,F33,G33) -> 2 | L17: =SUM(E49,F49,G49,E51,F51,G51,E62,F62,G62,E56,F56,G56,E66,F66,G66) -> 3 | M17: =SUM(E80,F80,G80,E82,F82,G82,E87,F87,G87,E93,F93,G93,E97,F97,G97) -> 6 | N17: =SUM(E110,F110,G110,E112,F112,G112,E117,F117,G117,E123,F123,G123,E127,F127,G127) -> 5 | O17: 0-2 | P17: 3 | Q17: 4-5 | R17: 6-10
C18: Conduct | D18: 7. Generally obedient, usually does what adults request | F18: 1 | J18: HyperActivity | K18: =SUM(E13,F13,G13,E21,F21,G21,E26,F26,G26,E32,F32,G32,E36,F36,G36) -> 7 | L18: =SUM(E46,F46,G46,E54,F54,G54,E65,F65,G65,E59,F59,G59,E69,F69,G69) -> 7 | M18: =SUM(E77,F77,G77,E85,F85,G85,E90,F90,G90,E96,F96,G96,E100,F100,G100) -> 8 | N18: =SUM(E107,F107,G107,E115,F115,G115,E120,F120,G120,E126,F126,G126,E130,F130,G130) -> 7 | O18: 0-5 | P18: 6-7 | Q18: 8 | R18: 9-10
C19: Emotional | D19: 8. Many worries, often seems worried | F19: 1 | J19: Total Difficulties | K19: =SUM(K15:K18) -> 20 | L19: =SUM(L15:L18) -> 21 | M19: =SUM(M15:M18) -> 24 | N19: =SUM(N15:N18) -> 23 | O19: 0-13 | P19: 14-16 | Q19: 17-19 | R19: 20-40
C20: Pro Social | D20: 9. Helpful if someone is hurt, upset or feeling ill | G20: 2 | J20: SubTotal Internalising | K20: =SUM(K15+K16) -> 11 | L20: =SUM(L15+L16) -> 11 | M20: =SUM(M15+M16) -> 10 | N20: =SUM(N15+N16) -> 11 | O20: 0-3 | P20: 4-7 | Q20: 8-10 | R20: 11-20
C21: HyperActivity | D21: 10. Constantly fidgeting or squirming | G21: 2 | J21: Sub Total Externalising | K21: =SUM(K17+K18) -> 9 | L21: =SUM(L17+L18) -> 10 | M21: =SUM(M17+M18) -> 14 | N21: =SUM(N17+N18) -> 12 | O21: 0-7 | P21: 8-10 | Q21: 11-13 | R21: 14-20
C22: Peer | D22: 11. Has at least one good friend | E22: 2 | J22: Impact | O22: 0-3 | P22: 4 | Q22: 5-6 | R22: 7-10
C23: Conduct | D23: 12. Often fights with other children or bullies them | E23: 0
C24: Emotional | D24: 13. Often unhappy, down-hearted or tearful | E24: 1 | J24: Pro Social | K24: =SUM(E12,F12,G12,E15,F15,G15,E20,F20,G20,E28,F28,G28,E31,F31,G31) -> 6 | L24: =SUM(E45,F45,G45,E48,F48,G48,E53,F53,G53,E61,F61,G61,E64,F64,G64) -> 6 | M24: =SUM(E76,F76,G76,E79,F79,G79,E84,F84,G84,E92,F92,G92,E95,F95,G95) -> 6 | N24: =SUM(E106,F106,G106,E109,F109,G109,E114,F114,G114,E122,F122,G122,E125,F125,G125) -> 6 | O24: 8-10 | P24: 7 | Q24: 6 | R24: 0-5
C25: Peer | D25: 14. Generally liked by other children | F25: 1
C26: HyperActivity | D26: 15. Easily distracted, concentration wanders | G26: 2
C27: Emotional | D27: 16. Nervous or clingy in new situations, easily loses confidence | F27: 1
C28: Pro Social | D28: 17. Kind to younger children | F28: 1
C29: Conduct | D29: 18. Often lies or cheats | E29: 0
C30: Peer | D30: 19. Picked on or bullied by other children | E30: 0
C31: Pro Social | D31: 20. Often volunteers to help others (parents, teachers, other children) | F31: 1
C32: HyperActivity | D32: 21. Thinks things out before acting | E32: 2
C33: Conduct | D33: 22. Steals from home, school or elsewhere | E33: 0
C34: Peer | D34: 23. Gets on better with adults than with other children | E34: 0
C35: Emotional | D35: 24. Many fears, easily scared | G35: 2
C36: HyperActivity | D36: 25. Sees tasks through to the end, good attention span | G36: 0
B41: Parent/ Carer 2 Completed SDQ | E41: Initials for consistency | J41: Data Checks:
C43: Category | D43: Statement | E43: Not True | F43: Sometimes | G43: TRUE | J43: Check: Every Question Answered & No Duplicate Answers
D44: Score | E44: 0 or 2 | F44: 1 | G44: 2 or 0 | J44: (note will be blank if no data entered on a particular SDQ)
C45: Pro Social | D45: 1. Considerate of other people’s feelings | E45: 0 | J45: Parent/Carer 1 | K45: {=_xlfn.LET( _xlpm.dataRange, E12:G36, _xlpm.rowCounts, _xlfn.BYROW(_xlpm.dataRange, _xlfn.LAMBDA(_xlpm.row, COUNTA(_xlpm.row))), _xlpm.valid, AND(_xlpm.rowCounts=1), IF(COUNTA(_xlpm.dataRange)=0, "", IF(_xlpm.valid, "Complete", "Incomplete")) )} -> Complete
C46: HyperActivity | D46: 2. Restless, overactive, cannot stay still for long | F46: 1 | J46: Parent/Carer 2 | K46: {=_xlfn.LET( _xlpm.dataRange, E45:G69, _xlpm.rowCounts, _xlfn.BYROW(_xlpm.dataRange, _xlfn.LAMBDA(_xlpm.row, COUNTA(_xlpm.row))), _xlpm.valid, AND(_xlpm.rowCounts=1), IF(COUNTA(_xlpm.dataRange)=0, "", IF(_xlpm.valid, "Complete", "Incomplete")) )} -> Complete
C47: Emotional | D47: 3. Often complains of headaches, stomach-aches or sickness | G47: 2 | J47: School | K47: {=_xlfn.LET( _xlpm.dataRange, E76:G100, _xlpm.rowCounts, _xlfn.BYROW(_xlpm.dataRange, _xlfn.LAMBDA(_xlpm.row, COUNTA(_xlpm.row))), _xlpm.valid, AND(_xlpm.rowCounts=1), IF(COUNTA(_xlpm.dataRange)=0, "", IF(_xlpm.valid, "Complete", "Incomplete")) )} -> Incomplete
C48: Pro Social | D48: 4. Shares readily with other children (treats, toys, pencils etc) | G48: 2 | J48: Self | K48: {=_xlfn.LET( _xlpm.dataRange, E106:G130, _xlpm.rowCounts, _xlfn.BYROW(_xlpm.dataRange, _xlfn.LAMBDA(_xlpm.row, COUNTA(_xlpm.row))), _xlpm.valid, AND(_xlpm.rowCounts=1), IF(COUNTA(_xlpm.dataRange)=0, "", IF(_xlpm.valid, "Complete", "Incomplete")) )} -> Incomplete
C49: Conduct | D49: 5. Often has temper tantrums or hot tempers | F49: 1
...

Sheet SDQ Period 2
C2: Instructions: | D2: Input: SDQ scores from Parent/Carer, School or Self Forms
D3: Input and calculate: Impact Score
D4: Check data: input table for errors/omissions and amend data as necessary
C6: Specify Date
B8: Parent/ Carer 1 Completed SDQ | E8: Initials for consistency
C10: Category | D10: Statement | E10: Not True | F10: Sometimes | G10: TRUE
D11: Score | E11: 0 or 2 | F11: 1 | G11: 2 or 0 | J11: Note: the 3 scoring columns below are formula driven so the cell cannot be altered EXCEPT for the colour to indicate changes in scores
C12: Pro Social | D12: 1. Considerate of other people’s feelings | E12: 0
C13: HyperActivity | D13: 2. Restless, overactive, cannot stay still for long | F13: 1 | J13: Scores
C14: Emotional | D14: 3. Often complains of headaches, stomach-aches or sickness | G14: 2 | J14: Category | K14: Parent/Carer 1 Score | L14: Parent/Carer 2 Score | M14: School | N14: Self Score | O14: Comparison - taken from parent scores only
C15: Pro Social | D15: 4. Shares readily with other children (treats, toys, pencils etc) | G15: 2 | J15: Emotional | K15: =SUM(E14,F14,G14,E19,F19,G19,E27,F27,G27,E24,F24,G24,E35,F35,G35) -> 8 | L15: =SUM(E47,F47,G47,E52,F52,G52,E60,F60,G60,E57,F57,G57,E68,F68,G68) -> 7 | M15: =SUM(E78,F78,G78,E83,F83,G83,E91,F91,G91,E88,F88,G88,E99,F99,G99) -> 7 | N15: =SUM(E108,F108,G108,E113,F113,G113,E118,F118,G118,E121,F121,G121,E129,F129,G129) -> 7 | O15: 0-3 | P15: 4 | Q15: 5-6 | R15: 7-10
C16: Conduct | D16: 5. Often has temper tantrums or hot tempers | F16: 1 | J16: Peer | K16: =SUM(E17,F17,G17,E22,F22,G22,E25,F25,G25,E30,F30,G30,E34,F34,G34) -> 3 | L16: =SUM(E50,F50,G50,E55,F55,G55,E58,F58,G58,E63,F63,G63,E67,F67,G67) -> 4 | M16: =SUM(E81,F81,G81,E86,F86,G86,E89,F89,G89,E94,F94,G94,E98,F98,G98) -> 3 | N16: =SUM(E111,F111,G111,E116,F116,G116,E119,F119,G119,E124,F124,G124,E128,F128,G128) -> 3 | O16: 0-2 | P16: 3 | Q16: 4 | R16: 5-10
C17: Peer | D17: 6. Rather solitary, tends to play alone | E17: 1 | J17: Conduct | K17: =SUM(E16,F16,G16,E18,F18,G18,E23,F23,G23,E29,F29,G29,E33,F33,G33) -> 3 | L17: =SUM(E49,F49,G49,E51,F51,G51,E62,F62,G62,E56,F56,G56,E66,F66,G66) -> 2 | M17: =SUM(E80,F80,G80,E82,F82,G82,E87,F87,G87,E93,F93,G93,E97,F97,G97) -> 6 | N17: =SUM(E110,F110,G110,E112,F112,G112,E117,F117,G117,E123,F123,G123,E127,F127,G127) -> 6 | O17: 0-2 | P17: 3 | Q17: 4-5 | R17: 6-10
C18: Conduct | D18: 7. Generally obedient, usually does what adults request | F18: 1 | J18: HyperActivity | K18: =SUM(E13,F13,G13,E21,F21,G21,E26,F26,G26,E32,F32,G32,E36,F36,G36) -> 7 | L18: =SUM(E46,F46,G46,E54,F54,G54,E65,F65,G65,E59,F59,G59,E69,F69,G69) -> 7 | M18: =SUM(E77,F77,G77,E85,F85,G85,E90,F90,G90,E96,F96,G96,E100,F100,G100) -> 8 | N18: =SUM(E107,F107,G107,E115,F115,G115,E120,F120,G120,E126,F126,G126,E130,F130,G130) -> 8 | O18: 0-5 | P18: 6-7 | Q18: 8 | R18: 9-10
C19: Emotional | D19: 8. Many worries, often seems worried | F19: 1 | J19: Total Difficulties | K19: =SUM(K15:K18) -> 21 | L19: =SUM(L15:L18) -> 20 | M19: =SUM(M15:M18) -> 24 | N19: =SUM(N15:N18) -> 24 | O19: 0-13 | P19: 14-16 | Q19: 17-19 | R19: 20-40
C20: Pro Social | D20: 9. Helpful if someone is hurt, upset or feeling ill | G20: 2 | J20: SubTotal Internalising | K20: =SUM(K15+K16) -> 11 | L20: =SUM(L15+L16) -> 11 | M20: =SUM(M15+M16) -> 10 | N20: =SUM(N15+N16) -> 10 | O20: 0-3 | P20: 4-7 | Q20: 8-10 | R20: 11-20
C21: HyperActivity | D21: 10. Constantly fidgeting or squirming | G21: 2 | J21: Sub Total Externalising | K21: =SUM(K17+K18) -> 10 | L21: =SUM(L17+L18) -> 9 | M21: =SUM(M17+M18) -> 14 | N21: =SUM(N17+N18) -> 14 | O21: 0-7 | P21: 8-10 | Q21: 11-13 | R21: 14-20
C22: Peer | D22: 11. Has at least one good friend | F22: 1 | J22: Impact | O22: 0-3 | P22: 4 | Q22: 5-6 | R22: 7-10
C23: Conduct | D23: 12. Often fights with other children or bullies them | F23: 1
C24: Emotional | D24: 13. Often unhappy, down-hearted or tearful | G24: 2 | J24: Pro Social | K24: =SUM(E12,F12,G12,E15,F15,G15,E20,F20,G20,E28,F28,G28,E31,F31,G31) -> 6 | L24: =SUM(E45,F45,G45,E48,F48,G48,E53,F53,G53,E61,F61,G61,E64,F64,G64) -> 6 | M24: =SUM(E76,F76,G76,E79,F79,G79,E84,F84,G84,E92,F92,G92,E95,F95,G95) -> 8 | N24: =SUM(E106,F106,G106,E109,F109,G109,E114,F114,G114,E122,F122,G122,E125,F125,G125) -> 6 | O24: 8-10 | P24: 7 | Q24: 6 | R24: 0-5
C25: Peer | D25: 14. Generally liked by other children | F25: 1
C26: HyperActivity | D26: 15. Easily distracted, concentration wanders | G26: 2
C27: Emotional | D27: 16. Nervous or clingy in new situations, easily loses confidence | F27: 1
C28: Pro Social | D28: 17. Kind to younger children | F28: 1
C29: Conduct | D29: 18. Often lies or cheats | E29: 0
C30: Peer | D30: 19. Picked on or bullied by other children | E30: 0
C31: Pro Social | D31: 20. Often volunteers to help others (parents, teachers, other children) | F31: 1
C32: HyperActivity | D32: 21. Thinks things out before acting | E32: 2
C33: Conduct | D33: 22. Steals from home, school or elsewhere | E33: 0
C34: Peer | D34: 23. Gets on better with adults than with other children | E34: 0
C35: Emotional | D35: 24. Many fears, easily scared | G35: 2
C36: HyperActivity | D36: 25. Sees tasks through to the end, good attention span | G36: 0
B41: Parent/ Carer 2 Completed SDQ | E41: Initials for consistency | J41: Data Checks:
C43: Category | D43: Statement | E43: Not True | F43: Sometimes | G43: TRUE | J43: Check: Every Question Answered & No Duplicate Answers
D44: Score | E44: 0 or 2 | F44: 1 | G44: 2 or 0 | J44: (note will be blank if no data entered on a particular SDQ)
C45: Pro Social | D45: 1. Considerate of other people’s feelings | E45: 0 | J45: Parent/Carer 1 | K45: {=_xlfn.LET( _xlpm.dataRange, E12:G36, _xlpm.rowCounts, _xlfn.BYROW(_xlpm.dataRange, _xlfn.LAMBDA(_xlpm.row, COUNTA(_xlpm.row))), _xlpm.valid, AND(_xlpm.rowCounts=1), IF(COUNTA(_xlpm.dataRange)=0, "", IF(_xlpm.valid, "Complete", "Incomplete")) )} -> Complete
C46: HyperActivity | D46: 2. Restless, overactive, cannot stay still for long | F46: 1 | J46: Parent/Carer 2 | K46: {=_xlfn.LET( _xlpm.dataRange, E45:G69, _xlpm.rowCounts, _xlfn.BYROW(_xlpm.dataRange, _xlfn.LAMBDA(_xlpm.row, COUNTA(_xlpm.row))), _xlpm.valid, AND(_xlpm.rowCounts=1), IF(COUNTA(_xlpm.dataRange)=0, "", IF(_xlpm.valid, "Complete", "Incomplete")) )} -> Complete
C47: Emotional | D47: 3. Often complains of headaches, stomach-aches or sickness | G47: 2 | J47: School | K47: {=_xlfn.LET( _xlpm.dataRange, E76:G100, _xlpm.rowCounts, _xlfn.BYROW(_xlpm.dataRange, _xlfn.LAMBDA(_xlpm.row, COUNTA(_xlpm.row))), _xlpm.valid, AND(_xlpm.rowCounts=1), IF(COUNTA(_xlpm.dataRange)=0, "", IF(_xlpm.valid, "Complete", "Incomplete")) )} -> Incomplete
C48: Pro Social | D48: 4. Shares readily with other children (treats, toys, pencils etc) | G48: 2 | J48: Self | K48: {=_xlfn.LET( _xlpm.dataRange, E106:G130, _xlpm.rowCounts, _xlfn.BYROW(_xlpm.dataRange, _xlfn.LAMBDA(_xlpm.row, COUNTA(_xlpm.row))), _xlpm.valid, AND(_xlpm.rowCounts=1), IF(COUNTA(_xlpm.dataRange)=0, "", IF(_xlpm.valid, "Complete", "Incomplete")) )} -> Incomplete
C49: Conduct | D49: 5. Often has temper tantrums or hot tempers | F49: 1
...

Sheet SDQ Period 3
C2: Instructions: | D2: Input: SDQ scores from Parent/Carer, School or Self Forms
D3: Input and calculate: Impact Score
D4: Check data: input table for errors/omissions and amend data as necessary
C6: Specify Date
B8: Parent/ Carer 1 Completed SDQ | E8: Initials for consistency
C10: Category | D10: Statement | E10: Not True | F10: Sometimes | G10: TRUE
D11: Score | E11: 0 or 2 | F11: 1 | G11: 2 or 0 | J11: Note: the 3 scoring columns below are formula driven so the cell cannot be altered EXCEPT for the colour to indicate changes in scores
C12: Pro Social | D12: 1. Considerate of other people’s feelings
C13: HyperActivity | D13: 2. Restless, overactive, cannot stay still for long | J13: Scores
C14: Emotional | D14: 3. Often complains of headaches, stomach-aches or sickness | J14: Category | K14: Parent/Carer 1 Score | L14: Parent/Carer 2 Score | M14: School Score | N14: Self Score | O14: Comparison - taken from parent scores only
C15: Pro Social | D15: 4. Shares readily with other children (treats, toys, pencils etc) | J15: Emotional | K15: =SUM(E14,F14,G14,E19,F19,G19,E27,F27,G27,E24,F24,G24,E35,F35,G35) -> 0 | L15: =SUM(E47,F47,G47,E52,F52,G52,E60,F60,G60,E57,F57,G57,E68,F68,G68) -> 0 | M15: =SUM(E78,F78,G78,E83,F83,G83,E91,F91,G91,E88,F88,G88,E99,F99,G99) -> 0 | N15: =SUM(E108,F108,G108,E113,F113,G113,E118,F118,G118,E121,F121,G121,E129,F129,G129) -> 0 | O15: 0-3 | P15: 4 | Q15: 5-6 | R15: 7-10
C16: Conduct | D16: 5. Often has temper tantrums or hot tempers | J16: Peer | K16: =SUM(E17,F17,G17,E22,F22,G22,E25,F25,G25,E30,F30,G30,E34,F34,G34) -> 0 | L16: =SUM(E50,F50,G50,E55,F55,G55,E58,F58,G58,E63,F63,G63,E67,F67,G67) -> 0 | M16: =SUM(E81,F81,G81,E86,F86,G86,E89,F89,G89,E94,F94,G94,E98,F98,G98) -> 0 | N16: =SUM(E111,F111,G111,E116,F116,G116,E119,F119,G119,E124,F124,G124,E128,F128,G128) -> 0 | O16: 0-2 | P16: 3 | Q16: 4 | R16: 5-10
C17: Peer | D17: 6. Rather solitary, tends to play alone | J17: Conduct | K17: =SUM(E16,F16,G16,E18,F18,G18,E23,F23,G23,E29,F29,G29,E33,F33,G33) -> 0 | L17: =SUM(E49,F49,G49,E51,F51,G51,E62,F62,G62,E56,F56,G56,E66,F66,G66) -> 0 | M17: =SUM(E80,F80,G80,E82,F82,G82,E87,F87,G87,E93,F93,G93,E97,F97,G97) -> 0 | N17: =SUM(E110,F110,G110,E112,F112,G112,E117,F117,G117,E123,F123,G123,E127,F127,G127) -> 0 | O17: 0-2 | P17: 3 | Q17: 4-5 | R17: 6-10
C18: Conduct | D18: 7. Generally obedient, usually does what adults request | J18: HyperActivity | K18: =SUM(E13,F13,G13,E21,F21,G21,E26,F26,G26,E32,F32,G32,E36,F36,G36) -> 0 | L18: =SUM(E46,F46,G46,E54,F54,G54,E65,F65,G65,E59,F59,G59,E69,F69,G69) -> 0 | M18: =SUM(E77,F77,G77,E85,F85,G85,E90,F90,G90,E96,F96,G96,E100,F100,G100) -> 0 | N18: =SUM(E107,F107,G107,E115,F115,G115,E120,F120,G120,E126,F126,G126,E130,F130,G130) -> 0 | O18: 0-5 | P18: 6-7 | Q18: 8 | R18: 9-10
C19: Emotional | D19: 8. Many worries, often seems worried | J19: Total Difficulties | K19: =SUM(K15:K18) -> 0 | L19: =SUM(L15:L18) -> 0 | M19: =SUM(M15:M18) -> 0 | N19: =SUM(N15:N18) -> 0 | O19: 0-13 | P19: 14-16 | Q19: 17-19 | R19: 20-40
C20: Pro Social | D20: 9. Helpful if someone is hurt, upset or feeling ill | J20: SubTotal Internalising | K20: =SUM(K15+K16) -> 0 | L20: =SUM(L15+L16) -> 0 | M20: =SUM(M15+M16) -> 0 | N20: =SUM(N15+N16) -> 0 | O20: 0-3 | P20: 4-7 | Q20: 8-10 | R20: 11-20
C21: HyperActivity | D21: 10. Constantly fidgeting or squirming | J21: Sub Total Externalising | K21: =SUM(K17+K18) -> 0 | L21: =SUM(L17+L18) -> 0 | M21: =SUM(M17+M18) -> 0 | N21: =SUM(N17+N18) -> 0 | O21: 0-7 | P21: 8-10 | Q21: 11-13 | R21: 14-20
C22: Peer | D22: 11. Has at least one good friend | J22: Impact | O22: 0-3 | P22: 4 | Q22: 5-6 | R22: 7-10
C23: Conduct | D23: 12. Often fights with other children or bullies them
C24: Emotional | D24: 13. Often unhappy, down-hearted or tearful | J24: Pro Social | K24: =SUM(E12,F12,G12,E15,F15,G15,E20,F20,G20,E28,F28,G28,E31,F31,G31) -> 0 | L24: =SUM(E45,F45,G45,E48,F48,G48,E53,F53,G53,E61,F61,G61,E64,F64,G64) -> 0 | M24: =SUM(E76,F76,G76,E79,F79,G79,E84,F84,G84,E92,F92,G92,E95,F95,G95) -> 0 | N24: =SUM(E106,F106,G106,E109,F109,G109,E114,F114,G114,E122,F122,G122,E125,F125,G125) -> 0 | O24: 8-10 | P24: 7 | Q24: 6 | R24: 0-5
C25: Peer | D25: 14. Generally liked by other children
C26: HyperActivity | D26: 15. Easily distracted, concentration wanders
C27: Emotional | D27: 16. Nervous or clingy in new situations, easily loses confidence
C28: Pro Social | D28: 17. Kind to younger children
C29: Conduct | D29: 18. Often lies or cheats
C30: Peer | D30: 19. Picked on or bullied by other children
C31: Pro Social | D31: 20. Often volunteers to help others (parents, teachers, other children)
C32: HyperActivity | D32: 21. Thinks things out before acting
C33: Conduct | D33: 22. Steals from home, school or elsewhere
C34: Peer | D34: 23. Gets on better with adults than with other children
C35: Emotional | D35: 24. Many fears, easily scared
C36: HyperActivity | D36: 25. Sees tasks through to the end, good attention span
B41: Parent/ Carer 2 Completed SDQ | E41: Initials for consistency | J41: Data Checks:
C43: Category | D43: Statement | E43: Not True | F43: Sometimes | G43: TRUE | J43: Check: Every Question Answered & No Duplicate Answers
D44: Score | E44: 0 or 2 | F44: 1 | G44: 2 or 0 | J44: (note will be blank if no data entered on a particular SDQ)
C45: Pro Social | D45: 1. Considerate of other people’s feelings | J45: Parent/Carer 1 | K45: {=_xlfn.LET( _xlpm.dataRange, E12:G36, _xlpm.rowCounts, _xlfn.BYROW(_xlpm.dataRange, _xlfn.LAMBDA(_xlpm.row, COUNTA(_xlpm.row))), _xlpm.valid, AND(_xlpm.rowCounts=1), IF(COUNTA(_xlpm.dataRange)=0, "", IF(_xlpm.valid, "Complete", "Incomplete")) )}
C46: HyperActivity | D46: 2. Restless, overactive, cannot stay still for long | J46: Parent/Carer 2 | K46: {=_xlfn.LET( _xlpm.dataRange, E45:G69, _xlpm.rowCounts, _xlfn.BYROW(_xlpm.dataRange, _xlfn.LAMBDA(_xlpm.row, COUNTA(_xlpm.row))), _xlpm.valid, AND(_xlpm.rowCounts=1), IF(COUNTA(_xlpm.dataRange)=0, "", IF(_xlpm.valid, "Complete", "Incomplete")) )}
C47: Emotional | D47: 3. Often complains of headaches, stomach-aches or sickness | J47: School | K47: {=_xlfn.LET( _xlpm.dataRange, E76:G100, _xlpm.rowCounts, _xlfn.BYROW(_xlpm.dataRange, _xlfn.LAMBDA(_xlpm.row, COUNTA(_xlpm.row))), _xlpm.valid, AND(_xlpm.rowCounts=1), IF(COUNTA(_xlpm.dataRange)=0, "", IF(_xlpm.valid, "Complete", "Incomplete")) )}
C48: Pro Social | D48: 4. Shares readily with other children (treats, toys, pencils etc) | J48: Self | K48: {=_xlfn.LET( _xlpm.dataRange, E106:G130, _xlpm.rowCounts, _xlfn.BYROW(_xlpm.dataRange, _xlfn.LAMBDA(_xlpm.row, COUNTA(_xlpm.row))), _xlpm.valid, AND(_xlpm.rowCounts=1), IF(COUNTA(_xlpm.dataRange)=0, "", IF(_xlpm.valid, "Complete", "Incomplete")) )}
C49: Conduct | D49: 5. Often has temper tantrums or hot tempers
...

Sheet SDQ Period 4
C2: Instructions: | D2: Input: SDQ scores from Parent/Carer, School or Self Forms
D3: Input and calculate: Impact Score
D4: Check data: input table for errors/omissions and amend data as necessary
C6: Specify Date
B8: Parent/ Carer 1 Completed SDQ | E8: Initials for consistency
C10: Category | D10: Statement | E10: Not True | F10: Sometimes | G10: TRUE
D11: Score | E11: 0 or 2 | F11: 1 | G11: 2 or 0 | J11: Note: the 3 scoring columns below are formula driven so the cell cannot be altered EXCEPT for the colour to indicate changes in scores
C12: Pro Social | D12: 1. Considerate of other people’s feelings
C13: HyperActivity | D13: 2. Restless, overactive, cannot stay still for long | J13: Scores
C14: Emotional | D14: 3. Often complains of headaches, stomach-aches or sickness | J14: Category | K14: Parent/Carer 1 Score | L14: Parent/Carer 2 Score | M14: School Score | N14: Self Score | O14: Comparison - taken from parent scores only
C15: Pro Social | D15: 4. Shares readily with other children (treats, toys, pencils etc) | J15: Emotional | K15: =SUM(E14,F14,G14,E19,F19,G19,E27,F27,G27,E24,F24,G24,E35,F35,G35) -> 0 | L15: =SUM(E47,F47,G47,E52,F52,G52,E60,F60,G60,E57,F57,G57,E68,F68,G68) -> 0 | M15: =SUM(E78,F78,G78,E83,F83,G83,E91,F91,G91,E88,F88,G88,E99,F99,G99) -> 0 | N15: =SUM(E108,F108,G108,E113,F113,G113,E118,F118,G118,E121,F121,G121,E129,F129,G129) -> 0 | O15: 0-3 | P15: 4 | Q15: 5-6 | R15: 7-10
C16: Conduct | D16: 5. Often has temper tantrums or hot tempers | J16: Peer | K16: =SUM(E17,F17,G17,E22,F22,G22,E25,F25,G25,E30,F30,G30,E34,F34,G34) -> 0 | L16: =SUM(E50,F50,G50,E55,F55,G55,E58,F58,G58,E63,F63,G63,E67,F67,G67) -> 0 | M16: =SUM(E81,F81,G81,E86,F86,G86,E89,F89,G89,E94,F94,G94,E98,F98,G98) -> 0 | N16: =SUM(E111,F111,G111,E116,F116,G116,E119,F119,G119,E124,F124,G124,E128,F128,G128) -> 0 | O16: 0-2 | P16: 3 | Q16: 4 | R16: 5-10
C17: Peer | D17: 6. Rather solitary, tends to play alone | J17: Conduct | K17: =SUM(E16,F16,G16,E18,F18,G18,E23,F23,G23,E29,F29,G29,E33,F33,G33) -> 0 | L17: =SUM(E49,F49,G49,E51,F51,G51,E62,F62,G62,E56,F56,G56,E66,F66,G66) -> 0 | M17: =SUM(E80,F80,G80,E82,F82,G82,E87,F87,G87,E93,F93,G93,E97,F97,G97) -> 0 | N17: =SUM(E110,F110,G110,E112,F112,G112,E117,F117,G117,E123,F123,G123,E127,F127,G127) -> 0 | O17: 0-2 | P17: 3 | Q17: 4-5 | R17: 6-10
C18: Conduct | D18: 7. Generally obedient, usually does what adults request | J18: HyperActivity | K18: =SUM(E13,F13,G13,E21,F21,G21,E26,F26,G26,E32,F32,G32,E36,F36,G36) -> 0 | L18: =SUM(E46,F46,G46,E54,F54,G54,E65,F65,G65,E59,F59,G59,E69,F69,G69) -> 0 | M18: =SUM(E77,F77,G77,E85,F85,G85,E90,F90,G90,E96,F96,G96,E100,F100,G100) -> 0 | N18: =SUM(E107,F107,G107,E115,F115,G115,E120,F120,G120,E126,F126,G126,E130,F130,G130) -> 0 | O18: 0-5 | P18: 6-7 | Q18: 8 | R18: 9-10
C19: Emotional | D19: 8. Many worries, often seems worried | J19: Total Difficulties | K19: =SUM(K15:K18) -> 0 | L19: =SUM(L15:L18) -> 0 | M19: =SUM(M15:M18) -> 0 | N19: =SUM(N15:N18) -> 0 | O19: 0-13 | P19: 14-16 | Q19: 17-19 | R19: 20-40
C20: Pro Social | D20: 9. Helpful if someone is hurt, upset or feeling ill | J20: SubTotal Internalising | K20: =SUM(K15+K16) -> 0 | L20: =SUM(L15+L16) -> 0 | M20: =SUM(M15+M16) -> 0 | N20: =SUM(N15+N16) -> 0 | O20: 0-3 | P20: 4-7 | Q20: 8-10 | R20: 11-20
C21: HyperActivity | D21: 10. Constantly fidgeting or squirming | J21: Sub Total Externalising | K21: =SUM(K17+K18) -> 0 | L21: =SUM(L17+L18) -> 0 | M21: =SUM(M17+M18) -> 0 | N21: =SUM(N17+N18) -> 0 | O21: 0-7 | P21: 8-10 | Q21: 11-13 | R21: 14-20
C22: Peer | D22: 11. Has at least one good friend | J22: Impact | O22: 0-3 | P22: 4 | Q22: 5-6 | R22: 7-10
C23: Conduct | D23: 12. Often fights with other children or bullies them
C24: Emotional | D24: 13. Often unhappy, down-hearted or tearful | J24: Pro Social | K24: =SUM(E12,F12,G12,E15,F15,G15,E20,F20,G20,E28,F28,G28,E31,F31,G31) -> 0 | L24: =SUM(E45,F45,G45,E48,F48,G48,E53,F53,G53,E61,F61,G61,E64,F64,G64) -> 0 | M24: =SUM(E76,F76,G76,E79,F79,G79,E84,F84,G84,E92,F92,G92,E95,F95,G95) -> 0 | N24: =SUM(E106,F106,G106,E109,F109,G109,E114,F114,G114,E122,F122,G122,E125,F125,G125) -> 0 | O24: 8-10 | P24: 7 | Q24: 6 | R24: 0-5
C25: Peer | D25: 14. Generally liked by other children
C26: HyperActivity | D26: 15. Easily distracted, concentration wanders
C27: Emotional | D27: 16. Nervous or clingy in new situations, easily loses confidence
C28: Pro Social | D28: 17. Kind to younger children
C29: Conduct | D29: 18. Often lies or cheats
C30: Peer | D30: 19. Picked on or bullied by other children
C31: Pro Social | D31: 20. Often volunteers to help others (parents, teachers, other children)
C32: HyperActivity | D32: 21. Thinks things out before acting
C33: Conduct | D33: 22. Steals from home, school or elsewhere
C34: Peer | D34: 23. Gets on better with adults than with other children
C35: Emotional | D35: 24. Many fears, easily scared
C36: HyperActivity | D36: 25. Sees tasks through to the end, good attention span
B41: Parent/ Carer 2 Completed SDQ | E41: Initials for consistency | J41: Data Checks:
C43: Category | D43: Statement | E43: Not True | F43: Sometimes | G43: TRUE | J43: Check: Every Question Answered & No Duplicate Answers
D44: Score | E44: 0 or 2 | F44: 1 | G44: 2 or 0 | J44: (note will be blank if no data entered on a particular SDQ)
C45: Pro Social | D45: 1. Considerate of other people’s feelings | J45: Parent/Carer 1 | K45: {=_xlfn.LET( _xlpm.dataRange, E12:G36, _xlpm.rowCounts, _xlfn.BYROW(_xlpm.dataRange, _xlfn.LAMBDA(_xlpm.row, COUNTA(_xlpm.row))), _xlpm.valid, AND(_xlpm.rowCounts=1), IF(COUNTA(_xlpm.dataRange)=0, "", IF(_xlpm.valid, "Complete", "Incomplete")) )}
C46: HyperActivity | D46: 2. Restless, overactive, cannot stay still for long | J46: Parent/Carer 2 | K46: {=_xlfn.LET( _xlpm.dataRange, E45:G69, _xlpm.rowCounts, _xlfn.BYROW(_xlpm.dataRange, _xlfn.LAMBDA(_xlpm.row, COUNTA(_xlpm.row))), _xlpm.valid, AND(_xlpm.rowCounts=1), IF(COUNTA(_xlpm.dataRange)=0, "", IF(_xlpm.valid, "Complete", "Incomplete")) )}
C47: Emotional | D47: 3. Often complains of headaches, stomach-aches or sickness | J47: School | K47: {=_xlfn.LET( _xlpm.dataRange, E76:G100, _xlpm.rowCounts, _xlfn.BYROW(_xlpm.dataRange, _xlfn.LAMBDA(_xlpm.row, COUNTA(_xlpm.row))), _xlpm.valid, AND(_xlpm.rowCounts=1), IF(COUNTA(_xlpm.dataRange)=0, "", IF(_xlpm.valid, "Complete", "Incomplete")) )}
C48: Pro Social | D48: 4. Shares readily with other children (treats, toys, pencils etc) | J48: Self | K48: {=_xlfn.LET( _xlpm.dataRange, E106:G130, _xlpm.rowCounts, _xlfn.BYROW(_xlpm.dataRange, _xlfn.LAMBDA(_xlpm.row, COUNTA(_xlpm.row))), _xlpm.valid, AND(_xlpm.rowCounts=1), IF(COUNTA(_xlpm.dataRange)=0, "", IF(_xlpm.valid, "Complete", "Incomplete")) )}
C49: Conduct | D49: 5. Often has temper tantrums or hot tempers
...

Sheet SDQ Period 5
C2: Instructions: | D2: Input: SDQ scores from Parent/Carer, School or Self Forms
D3: Input and calculate: Impact Score
D4: Check data: input table for errors/omissions and amend data as necessary
C6: Specify Date
B8: Parent/ Carer 1 Completed SDQ | E8: Initials for consistency
C10: Catergory | D10: Statement | E10: Not True | F10: Sometimes | G10: TRUE
D11: Score | E11: 0 or 2 | F11: 1 | G11: 2 or 0 | J11: Note: the 3 scoring columns below are formula driven so the cell cannot be altered EXCEPT for the colour to indicate changes in scores
C12: Pro Social | D12: 1. Considerate of other people’s feelings
C13: HyperActivity | D13: 2. Restless, overactive, cannot stay still for long | J13: Scores
C14: Emotional | D14: 3. Often complains of headaches, stomach-aches or sickness | J14: Category | K14: Parent/Carer 1 Score | L14: Parent/Carer 2 Score | M14: School Score | N14: Self Score | O14: Comparison - taken from parent scores only
C15: Pro Social | D15: 4. Shares readily with other children (treats, toys, pencils etc) | J15: Emotional | K15: =SUM(E14,F14,G14,E19,F19,G19,E27,F27,G27,E24,F24,G24,E35,F35,G35) -> 0 | L15: =SUM(E47,F47,G47,E52,F52,G52,E60,F60,G60,E57,F57,G57,E68,F68,G68) -> 0 | M15: =SUM(E78,F78,G78,E83,F83,G83,E91,F91,G91,E88,F88,G88,E99,F99,G99) -> 0 | N15: =SUM(E108,F108,G108,E113,F113,G113,E118,F118,G118,E121,F121,G121,E129,F129,G129) -> 0 | O15: 0-3 | P15: 4 | Q15: 5-6 | R15: 7-10
C16: Conduct | D16: 5. Often has temper tantrums or hot tempers | J16: Peer | K16: =SUM(E17,F17,G17,E22,F22,G22,E25,F25,G25,E30,F30,G30,E34,F34,G34) -> 0 | L16: =SUM(E50,F50,G50,E55,F55,G55,E58,F58,G58,E63,F63,G63,E67,F67,G67) -> 0 | M16: =SUM(E81,F81,G81,E86,F86,G86,E89,F89,G89,E94,F94,G94,E98,F98,G98) -> 0 | N16: =SUM(E111,F111,G111,E116,F116,G116,E119,F119,G119,E124,F124,G124,E128,F128,G128) -> 0 | O16: 0-2 | P16: 3 | Q16: 4 | R16: 5-10
C17: Peer | D17: 6. Rather solitary, tends to play alone | J17: Conduct | K17: =SUM(E16,F16,G16,E18,F18,G18,E23,F23,G23,E29,F29,G29,E33,F33,G33) -> 0 | L17: =SUM(E49,F49,G49,E51,F51,G51,E62,F62,G62,E56,F56,G56,E66,F66,G66) -> 0 | M17: =SUM(E80,F80,G80,E82,F82,G82,E87,F87,G87,E93,F93,G93,E97,F97,G97) -> 0 | N17: =SUM(E110,F110,G110,E112,F112,G112,E117,F117,G117,E123,F123,G123,E127,F127,G127) -> 0 | O17: 0-2 | P17: 3 | Q17: 4-5 | R17: 6-10
C18: Conduct | D18: 7. Generally obedient, usually does what adults request | J18: HyperActivity | K18: =SUM(E13,F13,G13,E21,F21,G21,E26,F26,G26,E32,F32,G32,E36,F36,G36) -> 0 | L18: =SUM(E46,F46,G46,E54,F54,G54,E65,F65,G65,E59,F59,G59,E69,F69,G69) -> 0 | M18: =SUM(E77,F77,G77,E85,F85,G85,E90,F90,G90,E96,F96,G96,E100,F100,G100) -> 0 | N18: =SUM(E107,F107,G107,E115,F115,G115,E120,F120,G120,E126,F126,G126,E130,F130,G130) -> 0 | O18: 0-5 | P18: 6-7 | Q18: 8 | R18: 9-10
C19: Emotional | D19: 8. Many worries, often seems worried | J19: Total Difficulties | K19: =SUM(K15:K18) -> 0 | L19: =SUM(L15:L18) -> 0 | M19: =SUM(M15:M18) -> 0 | N19: =SUM(N15:N18) -> 0 | O19: 0-13 | P19: 14-16 | Q19: 17-19 | R19: 20-40
C20: Pro Social | D20: 9. Helpful if someone is hurt, upset or feeling ill | J20: SubTotal Internalising | K20: =SUM(K15+K16) -> 0 | L20: =SUM(L15+L16) -> 0 | M20: =SUM(M15+M16) -> 0 | N20: =SUM(N15+N16) -> 0 | O20: 0-3 | P20: 4-7 | Q20: 8-10 | R20: 11-20
C21: HyperActivity | D21: 10. Constantly fidgeting or squirming | J21: Sub Total Externalising | K21: =SUM(K17+K18) -> 0 | L21: =SUM(L17+L18) -> 0 | M21: =SUM(M17+M18) -> 0 | N21: =SUM(N17+N18) -> 0 | O21: 0-7 | P21: 8-10 | Q21: 11-13 | R21: 14-20
C22: Peer | D22: 11. Has at least one good friend | J22: Impact | O22: 0-3 | P22: 4 | Q22: 5-6 | R22: 7-10
C23: Conduct | D23: 12. Often fights with other children or bullies them
C24: Emotional | D24: 13. Often unhappy, down-hearted or tearful | J24: Pro Social | K24: =SUM(E12,F12,G12,E15,F15,G15,E20,F20,G20,E28,F28,G28,E31,F31,G31) -> 0 | L24: =SUM(E45,F45,G45,E48,F48,G48,E53,F53,G53,E61,F61,G61,E64,F64,G64) -> 0 | M24: =SUM(E76,F76,G76,E79,F79,G79,E84,F84,G84,E92,F92,G92,E95,F95,G95) -> 0 | N24: =SUM(E106,F106,G106,E109,F109,G109,E114,F114,G114,E122,F122,G122,E125,F125,G125) -> 0 | O24: 8-10 | P24: 7 | Q24: 6 | R24: 0-5
C25: Peer | D25: 14. Generally liked by other children
C26: HyperActivity | D26: 15. Easily distracted, concentration wanders
C27: Emotional | D27: 16. Nervous or clingy in new situations, easily loses confidence
C28: Pro Social | D28: 17. Kind to younger children
C29: Conduct | D29: 18. Often lies or cheats
C30: Peer | D30: 19. Picked on or bullied by other children
C31: Pro Social | D31: 20. Often volunteers to help others (parents, teachers, other children)
C32: HyperActivity | D32: 21. Thinks things out before acting
C33: Conduct | D33: 22. Steals from home, school or elsewhere
C34: Peer | D34: 23. Gets on better with adults than with other children
C35: Emotional | D35: 24. Many fears, easily scared
C36: HyperActivity | D36: 25. Sees tasks through to the end, good attention span
B41: Parent/ Carer 2 Completed SDQ | E41: Initials for consistency | J41: Data Checks:
C43: Catergory | D43: Statement | E43: Not True | F43: Sometimes | G43: TRUE | J43: Check: Every Question Answered & No Duplicate Answers
D44: Score | E44: 0 or 2 | F44: 1 | G44: 2 or 0 | J44: (note will be blank if no data entered on a particular SDQ)
C45: Pro Social | D45: 1. Considerate of other people’s feelings | J45: Parent/Carer 1 | K45: {=_xlfn.LET( _xlpm.dataRange, E12:G36, _xlpm.rowCounts, _xlfn.BYROW(_xlpm.dataRange, _xlfn.LAMBDA(_xlpm.row, COUNTA(_xlpm.row))), _xlpm.valid, AND(_xlpm.rowCounts=1), IF(COUNTA(_xlpm.dataRange)=0, "", IF(_xlpm.valid, "Complete", "Incomplete")) )}
C46: HyperActivity | D46: 2. Restless, overactive, cannot stay still for long | J46: Parent/Carer 2 | K46: {=_xlfn.LET( _xlpm.dataRange, E45:G69, _xlpm.rowCounts, _xlfn.BYROW(_xlpm.dataRange, _xlfn.LAMBDA(_xlpm.row, COUNTA(_xlpm.row))), _xlpm.valid, AND(_xlpm.rowCounts=1), IF(COUNTA(_xlpm.dataRange)=0, "", IF(_xlpm.valid, "Complete", "Incomplete")) )}
C47: Emotional | D47: 3. Often complains of headaches, stomach-aches or sickness | J47: School | K47: {=_xlfn.LET( _xlpm.dataRange, E76:G100, _xlpm.rowCounts, _xlfn.BYROW(_xlpm.dataRange, _xlfn.LAMBDA(_xlpm.row, COUNTA(_xlpm.row))), _xlpm.valid, AND(_xlpm.rowCounts=1), IF(COUNTA(_xlpm.dataRange)=0, "", IF(_xlpm.valid, "Complete", "Incomplete")) )}
C48: Pro Social | D48: 4. Shares readily with other children (treats, toys, pencils etc) | J48: Self | K48: {=_xlfn.LET( _xlpm.dataRange, E106:G130, _xlpm.rowCounts, _xlfn.BYROW(_xlpm.dataRange, _xlfn.LAMBDA(_xlpm.row, COUNTA(_xlpm.row))), _xlpm.valid, AND(_xlpm.rowCounts=1), IF(COUNTA(_xlpm.dataRange)=0, "", IF(_xlpm.valid, "Complete", "Incomplete")) )}
C49: Conduct | D49: 5. Often has temper tantrums or hot tempers
...

Sheet SDQ Period 6
C2: Instructions: | D2: Input: SDQ scores from Parent/Carer, School or Self Forms
D3: Input and calculate: Impact Score
D4: Check data: input table for errors/omissions and amend data as necessary
C6: Specify Date
B8: Parent/ Carer 1 Completed SDQ | E8: Initials for consistency
C10: Category | D10: Statement | E10: Not True | F10: Sometimes | G10: TRUE
D11: Score | E11: 0 or 2 | F11: 1 | G11: 2 or 0 | J11: Note: the 3 scoring columns below are formula driven so the cell cannot be altered EXCEPT for the colour to indicate changes in scores
C12: Pro Social | D12: 1. Considerate of other people’s feelings
C13: HyperActivity | D13: 2. Restless, overactive, cannot stay still for long | J13: Scores
C14: Emotional | D14: 3. Often complains of headaches, stomach-aches or sickness | J14: Category | K14: Parent/Carer 1 Score | L14: Parent/Carer 2 Score | M14: School Score | N14: Self Score | O14: Comparison - taken from parent scores only
C15: Pro Social | D15: 4. Shares readily with other children (treats, toys, pencils etc) | J15: Emotional | K15: =SUM(E14,F14,G14,E19,F19,G19,E27,F27,G27,E24,F24,G24,E35,F35,G35) -> 0 | L15: =SUM(E47,F47,G47,E52,F52,G52,E60,F60,G60,E57,F57,G57,E68,F68,G68) -> 0 | M15: =SUM(E78,F78,G78,E83,F83,G83,E91,F91,G91,E88,F88,G88,E99,F99,G99) -> 0 | N15: =SUM(E108,F108,G108,E113,F113,G113,E118,F118,G118,E121,F121,G121,E129,F129,G129) -> 0 | O15: 0-3 | P15: 4 | Q15: 5-6 | R15: 7-10
C16: Conduct | D16: 5. Often has temper tantrums or hot tempers | J16: Peer | K16: =SUM(E17,F17,G17,E22,F22,G22,E25,F25,G25,E30,F30,G30,E34,F34,G34) -> 0 | L16: =SUM(E50,F50,G50,E55,F55,G55,E58,F58,G58,E63,F63,G63,E67,F67,G67) -> 0 | M16: =SUM(E81,F81,G81,E86,F86,G86,E89,F89,G89,E94,F94,G94,E98,F98,G98) -> 0 | N16: =SUM(E111,F111,G111,E116,F116,G116,E119,F119,G119,E124,F124,G124,E128,F128,G128) -> 0 | O16: 0-2 | P16: 3 | Q16: 4 | R16: 5-10
C17: Peer | D17: 6. Rather solitary, tends to play alone | J17: Conduct | K17: =SUM(E16,F16,G16,E18,F18,G18,E23,F23,G23,E29,F29,G29,E33,F33,G33) -> 0 | L17: =SUM(E49,F49,G49,E51,F51,G51,E62,F62,G62,E56,F56,G56,E66,F66,G66) -> 0 | M17: =SUM(E80,F80,G80,E82,F82,G82,E87,F87,G87,E93,F93,G93,E97,F97,G97) -> 0 | N17: =SUM(E110,F110,G110,E112,F112,G112,E117,F117,G117,E123,F123,G123,E127,F127,G127) -> 0 | O17: 0-2 | P17: 3 | Q17: 4-5 | R17: 6-10
C18: Conduct | D18: 7. Generally obedient, usually does what adults request | J18: HyperActivity | K18: =SUM(E13,F13,G13,E21,F21,G21,E26,F26,G26,E32,F32,G32,E36,F36,G36) -> 0 | L18: =SUM(E46,F46,G46,E54,F54,G54,E65,F65,G65,E59,F59,G59,E69,F69,G69) -> 0 | M18: =SUM(E77,F77,G77,E85,F85,G85,E90,F90,G90,E96,F96,G96,E100,F100,G100) -> 0 | N18: =SUM(E107,F107,G107,E115,F115,G115,E120,F120,G120,E126,F126,G126,E130,F130,G130) -> 0 | O18: 0-5 | P18: 6-7 | Q18: 8 | R18: 9-10
C19: Emotional | D19: 8. Many worries, often seems worried | J19: Total Difficulties | K19: =SUM(K15:K18) -> 0 | L19: =SUM(L15:L18) -> 0 | M19: =SUM(M15:M18) -> 0 | N19: =SUM(N15:N18) -> 0 | O19: 0-13 | P19: 14-16 | Q19: 17-19 | R19: 20-40
C20: Pro Social | D20: 9. Helpful if someone is hurt, upset or feeling ill | J20: SubTotal Internalising | K20: =SUM(K15+K16) -> 0 | L20: =SUM(L15+L16) -> 0 | M20: =SUM(M15+M16) -> 0 | N20: =SUM(N15+N16) -> 0 | O20: 0-3 | P20: 4-7 | Q20: 8-10 | R20: 11-20
C21: HyperActivity | D21: 10. Constantly fidgeting or squirming | J21: Sub Total Externalising | K21: =SUM(K17+K18) -> 0 | L21: =SUM(L17+L18) -> 0 | M21: =SUM(M17+M18) -> 0 | N21: =SUM(N17+N18) -> 0 | O21: 0-7 | P21: 8-10 | Q21: 11-13 | R21: 14-20
C22: Peer | D22: 11. Has at least one good friend | J22: Impact | O22: 0-3 | P22: 4 | Q22: 5-6 | R22: 7-10
C23: Conduct | D23: 12. Often fights with other children or bullies them
C24: Emotional | D24: 13. Often unhappy, down-hearted or tearful | J24: Pro Social | K24: =SUM(E12,F12,G12,E15,F15,G15,E20,F20,G20,E28,F28,G28,E31,F31,G31) -> 0 | L24: =SUM(E45,F45,G45,E48,F48,G48,E53,F53,G53,E61,F61,G61,E64,F64,G64) -> 0 | M24: =SUM(E76,F76,G76,E79,F79,G79,E84,F84,G84,E92,F92,G92,E95,F95,G95) -> 0 | N24: =SUM(E106,F106,G106,E109,F109,G109,E114,F114,G114,E122,F122,G122,E125,F125,G125) -> 0 | O24: 8-10 | P24: 7 | Q24: 6 | R24: 0-5
C25: Peer | D25: 14. Generally liked by other children
C26: HyperActivity | D26: 15. Easily distracted, concentration wanders
C27: Emotional | D27: 16. Nervous or clingy in new situations, easily loses confidence
C28: Pro Social | D28: 17. Kind to younger children
C29: Conduct | D29: 18. Often lies or cheats
C30: Peer | D30: 19. Picked on or bullied by other children
C31: Pro Social | D31: 20. Often volunteers to help others (parents, teachers, other children)
C32: HyperActivity | D32: 21. Thinks things out before acting
C33: Conduct | D33: 22. Steals from home, school or elsewhere
C34: Peer | D34: 23. Gets on better with adults than with other children
C35: Emotional | D35: 24. Many fears, easily scared
C36: HyperActivity | D36: 25. Sees tasks through to the end, good attention span
B41: Parent/ Carer 2 Completed SDQ | E41: Initials for consistency | J41: Data Checks:
C43: Category | D43: Statement | E43: Not True | F43: Sometimes | G43: TRUE | J43: Check: Every Question Answered & No Duplicate Answers
D44: Score | E44: 0 or 2 | F44: 1 | G44: 2 or 0 | J44: (note will be blank if no data entered on a particular SDQ)
C45: Pro Social | D45: 1. Considerate of other people’s feelings | J45: Parent/Carer 1 | K45: {=_xlfn.LET( _xlpm.dataRange, E12:G36, _xlpm.rowCounts, _xlfn.BYROW(_xlpm.dataRange, _xlfn.LAMBDA(_xlpm.row, COUNTA(_xlpm.row))), _xlpm.valid, AND(_xlpm.rowCounts=1), IF(COUNTA(_xlpm.dataRange)=0, "", IF(_xlpm.valid, "Complete", "Incomplete")) )}
C46: HyperActivity | D46: 2. Restless, overactive, cannot stay still for long | J46: Parent/Carer 2 | K46: {=_xlfn.LET( _xlpm.dataRange, E45:G69, _xlpm.rowCounts, _xlfn.BYROW(_xlpm.dataRange, _xlfn.LAMBDA(_xlpm.row, COUNTA(_xlpm.row))), _xlpm.valid, AND(_xlpm.rowCounts=1), IF(COUNTA(_xlpm.dataRange)=0, "", IF(_xlpm.valid, "Complete", "Incomplete")) )}
C47: Emotional | D47: 3. Often complains of headaches, stomach-aches or sickness | J47: School | K47: {=_xlfn.LET( _xlpm.dataRange, E76:G100, _xlpm.rowCounts, _xlfn.BYROW(_xlpm.dataRange, _xlfn.LAMBDA(_xlpm.row, COUNTA(_xlpm.row))), _xlpm.valid, AND(_xlpm.rowCounts=1), IF(COUNTA(_xlpm.dataRange)=0, "", IF(_xlpm.valid, "Complete", "Incomplete")) )}
C48: Pro Social | D48: 4. Shares readily with other children (treats, toys, pencils etc) | J48: Self | K48: {=_xlfn.LET( _xlpm.dataRange, E106:G130, _xlpm.rowCounts, _xlfn.BYROW(_xlpm.dataRange, _xlfn.LAMBDA(_xlpm.row, COUNTA(_xlpm.row))), _xlpm.valid, AND(_xlpm.rowCounts=1), IF(COUNTA(_xlpm.dataRange)=0, "", IF(_xlpm.valid, "Complete", "Incomplete")) )}
C49: Conduct | D49: 5. Often has temper tantrums or hot tempers
...

Sheet SDQ Period 7
C2: Instructions: | D2: Input: SDQ scores from Parent/Carer, School or Self Forms
D3: Input and calculate: Impact Score
